2024-03-12 16:31:48 | ERROR | 415 Unsupported Media Type: Did not attempt to load JSON data because the request Content-Type was not 'application/json'.
2024-03-12 16:31:48 | ERROR | Traceback (most recent call last):
  File "C:\Users\roberttm\Documents\proyectos\App permisos y ausencias\app-permisos-ausencias\src\routes\PermissionRoutes.py", line 54, in create_permission
    dni = request.json['dni']
          ^^^^^^^^^^^^
  File "C:\Users\roberttm\Documents\proyectos\App permisos y ausencias\app-permisos-ausencias\.venv\Lib\site-packages\werkzeug\wrappers\request.py", line 558, in json
    return self.get_json()
           ^^^^^^^^^^^^^^^
  File "C:\Users\roberttm\Documents\proyectos\App permisos y ausencias\app-permisos-ausencias\.venv\Lib\site-packages\werkzeug\wrappers\request.py", line 604, in get_json
    return self.on_json_loading_failed(None)
           ^^^^^^^^^^^^^^^^^^^^^^^^^^^^^^^^^
  File "C:\Users\roberttm\Documents\proyectos\App permisos y ausencias\app-permisos-ausencias\.venv\Lib\site-packages\flask\wrappers.py", line 131, in on_json_loading_failed
    return super().on_json_loading_failed(e)
           ^^^^^^^^^^^^^^^^^^^^^^^^^^^^^^^^^
  File "C:\Users\roberttm\Documents\proyectos\App permisos y ausencias\app-permisos-ausencias\.venv\Lib\site-packages\werkzeug\wrappers\request.py", line 647, in on_json_loading_failed
    raise UnsupportedMediaType(
werkzeug.exceptions.UnsupportedMediaType: 415 Unsupported Media Type: Did not attempt to load JSON data because the request Content-Type was not 'application/json'.

2024-03-12 16:35:47 | ERROR | 415 Unsupported Media Type: Did not attempt to load JSON data because the request Content-Type was not 'application/json'.
2024-03-12 16:35:47 | ERROR | Traceback (most recent call last):
  File "C:\Users\roberttm\Documents\proyectos\App permisos y ausencias\app-permisos-ausencias\src\routes\PermissionRoutes.py", line 54, in create_permission
    dni = request.json['dni']
          ^^^^^^^^^^^^
  File "C:\Users\roberttm\Documents\proyectos\App permisos y ausencias\app-permisos-ausencias\.venv\Lib\site-packages\werkzeug\wrappers\request.py", line 558, in json
    return self.get_json()
           ^^^^^^^^^^^^^^^
  File "C:\Users\roberttm\Documents\proyectos\App permisos y ausencias\app-permisos-ausencias\.venv\Lib\site-packages\werkzeug\wrappers\request.py", line 604, in get_json
    return self.on_json_loading_failed(None)
           ^^^^^^^^^^^^^^^^^^^^^^^^^^^^^^^^^
  File "C:\Users\roberttm\Documents\proyectos\App permisos y ausencias\app-permisos-ausencias\.venv\Lib\site-packages\flask\wrappers.py", line 131, in on_json_loading_failed
    return super().on_json_loading_failed(e)
           ^^^^^^^^^^^^^^^^^^^^^^^^^^^^^^^^^
  File "C:\Users\roberttm\Documents\proyectos\App permisos y ausencias\app-permisos-ausencias\.venv\Lib\site-packages\werkzeug\wrappers\request.py", line 647, in on_json_loading_failed
    raise UnsupportedMediaType(
werkzeug.exceptions.UnsupportedMediaType: 415 Unsupported Media Type: Did not attempt to load JSON data because the request Content-Type was not 'application/json'.

2024-03-12 16:35:52 | ERROR | 415 Unsupported Media Type: Did not attempt to load JSON data because the request Content-Type was not 'application/json'.
2024-03-12 16:35:52 | ERROR | Traceback (most recent call last):
  File "C:\Users\roberttm\Documents\proyectos\App permisos y ausencias\app-permisos-ausencias\src\routes\PermissionRoutes.py", line 54, in create_permission
    dni = request.json['dni']
          ^^^^^^^^^^^^
  File "C:\Users\roberttm\Documents\proyectos\App permisos y ausencias\app-permisos-ausencias\.venv\Lib\site-packages\werkzeug\wrappers\request.py", line 558, in json
    return self.get_json()
           ^^^^^^^^^^^^^^^
  File "C:\Users\roberttm\Documents\proyectos\App permisos y ausencias\app-permisos-ausencias\.venv\Lib\site-packages\werkzeug\wrappers\request.py", line 604, in get_json
    return self.on_json_loading_failed(None)
           ^^^^^^^^^^^^^^^^^^^^^^^^^^^^^^^^^
  File "C:\Users\roberttm\Documents\proyectos\App permisos y ausencias\app-permisos-ausencias\.venv\Lib\site-packages\flask\wrappers.py", line 131, in on_json_loading_failed
    return super().on_json_loading_failed(e)
           ^^^^^^^^^^^^^^^^^^^^^^^^^^^^^^^^^
  File "C:\Users\roberttm\Documents\proyectos\App permisos y ausencias\app-permisos-ausencias\.venv\Lib\site-packages\werkzeug\wrappers\request.py", line 647, in on_json_loading_failed
    raise UnsupportedMediaType(
werkzeug.exceptions.UnsupportedMediaType: 415 Unsupported Media Type: Did not attempt to load JSON data because the request Content-Type was not 'application/json'.

2024-03-12 16:36:40 | ERROR | 415 Unsupported Media Type: Did not attempt to load JSON data because the request Content-Type was not 'application/json'.
2024-03-12 16:36:40 | ERROR | Traceback (most recent call last):
  File "C:\Users\roberttm\Documents\proyectos\App permisos y ausencias\app-permisos-ausencias\src\routes\PermissionRoutes.py", line 54, in create_permission
    dni = request.json['dni']
          ^^^^^^^^^^^^
  File "C:\Users\roberttm\Documents\proyectos\App permisos y ausencias\app-permisos-ausencias\.venv\Lib\site-packages\werkzeug\wrappers\request.py", line 558, in json
    return self.get_json()
           ^^^^^^^^^^^^^^^
  File "C:\Users\roberttm\Documents\proyectos\App permisos y ausencias\app-permisos-ausencias\.venv\Lib\site-packages\werkzeug\wrappers\request.py", line 604, in get_json
    return self.on_json_loading_failed(None)
           ^^^^^^^^^^^^^^^^^^^^^^^^^^^^^^^^^
  File "C:\Users\roberttm\Documents\proyectos\App permisos y ausencias\app-permisos-ausencias\.venv\Lib\site-packages\flask\wrappers.py", line 131, in on_json_loading_failed
    return super().on_json_loading_failed(e)
           ^^^^^^^^^^^^^^^^^^^^^^^^^^^^^^^^^
  File "C:\Users\roberttm\Documents\proyectos\App permisos y ausencias\app-permisos-ausencias\.venv\Lib\site-packages\werkzeug\wrappers\request.py", line 647, in on_json_loading_failed
    raise UnsupportedMediaType(
werkzeug.exceptions.UnsupportedMediaType: 415 Unsupported Media Type: Did not attempt to load JSON data because the request Content-Type was not 'application/json'.

2024-03-12 17:09:40 | ERROR | 415 Unsupported Media Type: Did not attempt to load JSON data because the request Content-Type was not 'application/json'.
2024-03-12 17:09:40 | ERROR | Traceback (most recent call last):
  File "C:\Users\roberttm\Documents\proyectos\App permisos y ausencias\app-permisos-ausencias\src\routes\PermissionRoutes.py", line 55, in create_permission
    dni = request.json['dni']
          ^^^^^^^^^^^^
  File "C:\Users\roberttm\Documents\proyectos\App permisos y ausencias\app-permisos-ausencias\.venv\Lib\site-packages\werkzeug\wrappers\request.py", line 558, in json
    return self.get_json()
           ^^^^^^^^^^^^^^^
  File "C:\Users\roberttm\Documents\proyectos\App permisos y ausencias\app-permisos-ausencias\.venv\Lib\site-packages\werkzeug\wrappers\request.py", line 604, in get_json
    return self.on_json_loading_failed(None)
           ^^^^^^^^^^^^^^^^^^^^^^^^^^^^^^^^^
  File "C:\Users\roberttm\Documents\proyectos\App permisos y ausencias\app-permisos-ausencias\.venv\Lib\site-packages\flask\wrappers.py", line 131, in on_json_loading_failed
    return super().on_json_loading_failed(e)
           ^^^^^^^^^^^^^^^^^^^^^^^^^^^^^^^^^
  File "C:\Users\roberttm\Documents\proyectos\App permisos y ausencias\app-permisos-ausencias\.venv\Lib\site-packages\werkzeug\wrappers\request.py", line 647, in on_json_loading_failed
    raise UnsupportedMediaType(
werkzeug.exceptions.UnsupportedMediaType: 415 Unsupported Media Type: Did not attempt to load JSON data because the request Content-Type was not 'application/json'.

2024-03-12 17:10:09 | ERROR | 415 Unsupported Media Type: Did not attempt to load JSON data because the request Content-Type was not 'application/json'.
2024-03-12 17:10:09 | ERROR | Traceback (most recent call last):
  File "C:\Users\roberttm\Documents\proyectos\App permisos y ausencias\app-permisos-ausencias\src\routes\PermissionRoutes.py", line 55, in create_permission
    dni = request.json['dni']
          ^^^^^^^^^^^^
  File "C:\Users\roberttm\Documents\proyectos\App permisos y ausencias\app-permisos-ausencias\.venv\Lib\site-packages\werkzeug\wrappers\request.py", line 558, in json
    return self.get_json()
           ^^^^^^^^^^^^^^^
  File "C:\Users\roberttm\Documents\proyectos\App permisos y ausencias\app-permisos-ausencias\.venv\Lib\site-packages\werkzeug\wrappers\request.py", line 604, in get_json
    return self.on_json_loading_failed(None)
           ^^^^^^^^^^^^^^^^^^^^^^^^^^^^^^^^^
  File "C:\Users\roberttm\Documents\proyectos\App permisos y ausencias\app-permisos-ausencias\.venv\Lib\site-packages\flask\wrappers.py", line 131, in on_json_loading_failed
    return super().on_json_loading_failed(e)
           ^^^^^^^^^^^^^^^^^^^^^^^^^^^^^^^^^
  File "C:\Users\roberttm\Documents\proyectos\App permisos y ausencias\app-permisos-ausencias\.venv\Lib\site-packages\werkzeug\wrappers\request.py", line 647, in on_json_loading_failed
    raise UnsupportedMediaType(
werkzeug.exceptions.UnsupportedMediaType: 415 Unsupported Media Type: Did not attempt to load JSON data because the request Content-Type was not 'application/json'.

2024-03-12 17:14:01 | ERROR | 415 Unsupported Media Type: Did not attempt to load JSON data because the request Content-Type was not 'application/json'.
2024-03-12 17:14:01 | ERROR | Traceback (most recent call last):
  File "C:\Users\roberttm\Documents\proyectos\App permisos y ausencias\app-permisos-ausencias\src\routes\PermissionRoutes.py", line 55, in create_permission
    dni = request.json['dni']
          ^^^^^^^^^^^^
  File "C:\Users\roberttm\Documents\proyectos\App permisos y ausencias\app-permisos-ausencias\.venv\Lib\site-packages\werkzeug\wrappers\request.py", line 558, in json
    return self.get_json()
           ^^^^^^^^^^^^^^^
  File "C:\Users\roberttm\Documents\proyectos\App permisos y ausencias\app-permisos-ausencias\.venv\Lib\site-packages\werkzeug\wrappers\request.py", line 604, in get_json
    return self.on_json_loading_failed(None)
           ^^^^^^^^^^^^^^^^^^^^^^^^^^^^^^^^^
  File "C:\Users\roberttm\Documents\proyectos\App permisos y ausencias\app-permisos-ausencias\.venv\Lib\site-packages\flask\wrappers.py", line 131, in on_json_loading_failed
    return super().on_json_loading_failed(e)
           ^^^^^^^^^^^^^^^^^^^^^^^^^^^^^^^^^
  File "C:\Users\roberttm\Documents\proyectos\App permisos y ausencias\app-permisos-ausencias\.venv\Lib\site-packages\werkzeug\wrappers\request.py", line 647, in on_json_loading_failed
    raise UnsupportedMediaType(
werkzeug.exceptions.UnsupportedMediaType: 415 Unsupported Media Type: Did not attempt to load JSON data because the request Content-Type was not 'application/json'.

2024-03-12 17:14:33 | ERROR | 415 Unsupported Media Type: Did not attempt to load JSON data because the request Content-Type was not 'application/json'.
2024-03-12 17:14:33 | ERROR | Traceback (most recent call last):
  File "C:\Users\roberttm\Documents\proyectos\App permisos y ausencias\app-permisos-ausencias\src\routes\PermissionRoutes.py", line 54, in create_permission
    dni = request.json['dni']
          ^^^^^^^^^^^^
  File "C:\Users\roberttm\Documents\proyectos\App permisos y ausencias\app-permisos-ausencias\.venv\Lib\site-packages\werkzeug\wrappers\request.py", line 558, in json
    return self.get_json()
           ^^^^^^^^^^^^^^^
  File "C:\Users\roberttm\Documents\proyectos\App permisos y ausencias\app-permisos-ausencias\.venv\Lib\site-packages\werkzeug\wrappers\request.py", line 604, in get_json
    return self.on_json_loading_failed(None)
           ^^^^^^^^^^^^^^^^^^^^^^^^^^^^^^^^^
  File "C:\Users\roberttm\Documents\proyectos\App permisos y ausencias\app-permisos-ausencias\.venv\Lib\site-packages\flask\wrappers.py", line 131, in on_json_loading_failed
    return super().on_json_loading_failed(e)
           ^^^^^^^^^^^^^^^^^^^^^^^^^^^^^^^^^
  File "C:\Users\roberttm\Documents\proyectos\App permisos y ausencias\app-permisos-ausencias\.venv\Lib\site-packages\werkzeug\wrappers\request.py", line 647, in on_json_loading_failed
    raise UnsupportedMediaType(
werkzeug.exceptions.UnsupportedMediaType: 415 Unsupported Media Type: Did not attempt to load JSON data because the request Content-Type was not 'application/json'.

2024-03-12 17:14:35 | ERROR | 415 Unsupported Media Type: Did not attempt to load JSON data because the request Content-Type was not 'application/json'.
2024-03-12 17:14:35 | ERROR | Traceback (most recent call last):
  File "C:\Users\roberttm\Documents\proyectos\App permisos y ausencias\app-permisos-ausencias\src\routes\PermissionRoutes.py", line 54, in create_permission
    dni = request.json['dni']
          ^^^^^^^^^^^^
  File "C:\Users\roberttm\Documents\proyectos\App permisos y ausencias\app-permisos-ausencias\.venv\Lib\site-packages\werkzeug\wrappers\request.py", line 558, in json
    return self.get_json()
           ^^^^^^^^^^^^^^^
  File "C:\Users\roberttm\Documents\proyectos\App permisos y ausencias\app-permisos-ausencias\.venv\Lib\site-packages\werkzeug\wrappers\request.py", line 604, in get_json
    return self.on_json_loading_failed(None)
           ^^^^^^^^^^^^^^^^^^^^^^^^^^^^^^^^^
  File "C:\Users\roberttm\Documents\proyectos\App permisos y ausencias\app-permisos-ausencias\.venv\Lib\site-packages\flask\wrappers.py", line 131, in on_json_loading_failed
    return super().on_json_loading_failed(e)
           ^^^^^^^^^^^^^^^^^^^^^^^^^^^^^^^^^
  File "C:\Users\roberttm\Documents\proyectos\App permisos y ausencias\app-permisos-ausencias\.venv\Lib\site-packages\werkzeug\wrappers\request.py", line 647, in on_json_loading_failed
    raise UnsupportedMediaType(
werkzeug.exceptions.UnsupportedMediaType: 415 Unsupported Media Type: Did not attempt to load JSON data because the request Content-Type was not 'application/json'.

2024-03-12 17:14:37 | ERROR | 415 Unsupported Media Type: Did not attempt to load JSON data because the request Content-Type was not 'application/json'.
2024-03-12 17:14:37 | ERROR | Traceback (most recent call last):
  File "C:\Users\roberttm\Documents\proyectos\App permisos y ausencias\app-permisos-ausencias\src\routes\PermissionRoutes.py", line 54, in create_permission
    dni = request.json['dni']
          ^^^^^^^^^^^^
  File "C:\Users\roberttm\Documents\proyectos\App permisos y ausencias\app-permisos-ausencias\.venv\Lib\site-packages\werkzeug\wrappers\request.py", line 558, in json
    return self.get_json()
           ^^^^^^^^^^^^^^^
  File "C:\Users\roberttm\Documents\proyectos\App permisos y ausencias\app-permisos-ausencias\.venv\Lib\site-packages\werkzeug\wrappers\request.py", line 604, in get_json
    return self.on_json_loading_failed(None)
           ^^^^^^^^^^^^^^^^^^^^^^^^^^^^^^^^^
  File "C:\Users\roberttm\Documents\proyectos\App permisos y ausencias\app-permisos-ausencias\.venv\Lib\site-packages\flask\wrappers.py", line 131, in on_json_loading_failed
    return super().on_json_loading_failed(e)
           ^^^^^^^^^^^^^^^^^^^^^^^^^^^^^^^^^
  File "C:\Users\roberttm\Documents\proyectos\App permisos y ausencias\app-permisos-ausencias\.venv\Lib\site-packages\werkzeug\wrappers\request.py", line 647, in on_json_loading_failed
    raise UnsupportedMediaType(
werkzeug.exceptions.UnsupportedMediaType: 415 Unsupported Media Type: Did not attempt to load JSON data because the request Content-Type was not 'application/json'.

2024-03-12 17:20:58 | ERROR | 415 Unsupported Media Type: Did not attempt to load JSON data because the request Content-Type was not 'application/json'.
2024-03-12 17:20:58 | ERROR | Traceback (most recent call last):
  File "C:\Users\roberttm\Documents\proyectos\App permisos y ausencias\app-permisos-ausencias\src\routes\PermissionRoutes.py", line 54, in create_permission
    dni = request.json['dni']
          ^^^^^^^^^^^^
  File "C:\Users\roberttm\Documents\proyectos\App permisos y ausencias\app-permisos-ausencias\.venv\Lib\site-packages\werkzeug\wrappers\request.py", line 558, in json
    return self.get_json()
           ^^^^^^^^^^^^^^^
  File "C:\Users\roberttm\Documents\proyectos\App permisos y ausencias\app-permisos-ausencias\.venv\Lib\site-packages\werkzeug\wrappers\request.py", line 604, in get_json
    return self.on_json_loading_failed(None)
           ^^^^^^^^^^^^^^^^^^^^^^^^^^^^^^^^^
  File "C:\Users\roberttm\Documents\proyectos\App permisos y ausencias\app-permisos-ausencias\.venv\Lib\site-packages\flask\wrappers.py", line 131, in on_json_loading_failed
    return super().on_json_loading_failed(e)
           ^^^^^^^^^^^^^^^^^^^^^^^^^^^^^^^^^
  File "C:\Users\roberttm\Documents\proyectos\App permisos y ausencias\app-permisos-ausencias\.venv\Lib\site-packages\werkzeug\wrappers\request.py", line 647, in on_json_loading_failed
    raise UnsupportedMediaType(
werkzeug.exceptions.UnsupportedMediaType: 415 Unsupported Media Type: Did not attempt to load JSON data because the request Content-Type was not 'application/json'.

2024-03-12 20:32:50 | ERROR | 'utf-8' codec can't decode byte 0xab in position 96: invalid start byte
2024-03-12 20:32:50 | ERROR | object of type 'NoneType' has no len()
2024-03-12 20:32:50 | ERROR | Traceback (most recent call last):
  File "D:\Terranova\proyectos\App control de permisos\src\routes\PermissionRoutes.py", line 18, in index
    if (len(permissions) > 0):
        ^^^^^^^^^^^^^^^^
TypeError: object of type 'NoneType' has no len()

2024-03-12 20:58:28 | ERROR | 400 Bad Request: The browser (or proxy) sent a request that this server could not understand.
2024-03-12 20:58:28 | ERROR | Traceback (most recent call last):
  File "D:\Terranova\proyectos\App control de permisos\src\routes\PermissionRoutes.py", line 51, in create_permission
    dni = request.form['dni']
          ~~~~~~~~~~~~^^^^^^^
  File "D:\Terranova\proyectos\App control de permisos\.venv\Lib\site-packages\werkzeug\datastructures\structures.py", line 192, in __getitem__
    raise exceptions.BadRequestKeyError(key)
werkzeug.exceptions.BadRequestKeyError: 400 Bad Request: The browser (or proxy) sent a request that this server could not understand.

2024-03-12 20:58:37 | ERROR | 400 Bad Request: The browser (or proxy) sent a request that this server could not understand.
2024-03-12 20:58:37 | ERROR | Traceback (most recent call last):
  File "D:\Terranova\proyectos\App control de permisos\src\routes\PermissionRoutes.py", line 51, in create_permission
    dni = request.form['dni']
          ~~~~~~~~~~~~^^^^^^^
  File "D:\Terranova\proyectos\App control de permisos\.venv\Lib\site-packages\werkzeug\datastructures\structures.py", line 192, in __getitem__
    raise exceptions.BadRequestKeyError(key)
werkzeug.exceptions.BadRequestKeyError: 400 Bad Request: The browser (or proxy) sent a request that this server could not understand.

2024-03-12 20:59:09 | ERROR | 'permission_date'
2024-03-12 20:59:09 | ERROR | Traceback (most recent call last):
  File "D:\Terranova\proyectos\App control de permisos\src\routes\PermissionRoutes.py", line 55, in create_permission
    permission_date = request.json['permission_date']
                      ~~~~~~~~~~~~^^^^^^^^^^^^^^^^^^^
KeyError: 'permission_date'

2024-03-12 21:00:00 | ERROR | 'permission_date'
2024-03-12 21:00:00 | ERROR | Traceback (most recent call last):
  File "D:\Terranova\proyectos\App control de permisos\src\routes\PermissionRoutes.py", line 55, in create_permission
    permission_date = request.json['permission_date']
                      ~~~~~~~~~~~~^^^^^^^^^^^^^^^^^^^
KeyError: 'permission_date'

2024-03-12 21:08:52 | ERROR | 415 Unsupported Media Type: Did not attempt to load JSON data because the request Content-Type was not 'application/json'.
2024-03-12 21:08:52 | ERROR | Traceback (most recent call last):
  File "D:\Terranova\proyectos\App control de permisos\src\routes\PermissionRoutes.py", line 53, in create_permission
    dni = request.json['dni']
          ^^^^^^^^^^^^
  File "D:\Terranova\proyectos\App control de permisos\.venv\Lib\site-packages\werkzeug\wrappers\request.py", line 558, in json
    return self.get_json()
           ^^^^^^^^^^^^^^^
  File "D:\Terranova\proyectos\App control de permisos\.venv\Lib\site-packages\werkzeug\wrappers\request.py", line 604, in get_json
    return self.on_json_loading_failed(None)
           ^^^^^^^^^^^^^^^^^^^^^^^^^^^^^^^^^
  File "D:\Terranova\proyectos\App control de permisos\.venv\Lib\site-packages\flask\wrappers.py", line 131, in on_json_loading_failed
    return super().on_json_loading_failed(e)
           ^^^^^^^^^^^^^^^^^^^^^^^^^^^^^^^^^
  File "D:\Terranova\proyectos\App control de permisos\.venv\Lib\site-packages\werkzeug\wrappers\request.py", line 647, in on_json_loading_failed
    raise UnsupportedMediaType(
werkzeug.exceptions.UnsupportedMediaType: 415 Unsupported Media Type: Did not attempt to load JSON data because the request Content-Type was not 'application/json'.

2024-03-12 21:09:15 | ERROR | 415 Unsupported Media Type: Did not attempt to load JSON data because the request Content-Type was not 'application/json'.
2024-03-12 21:09:15 | ERROR | Traceback (most recent call last):
  File "D:\Terranova\proyectos\App control de permisos\src\routes\PermissionRoutes.py", line 53, in create_permission
    dni = request.json['dni']
          ^^^^^^^^^^^^
  File "D:\Terranova\proyectos\App control de permisos\.venv\Lib\site-packages\werkzeug\wrappers\request.py", line 558, in json
    return self.get_json()
           ^^^^^^^^^^^^^^^
  File "D:\Terranova\proyectos\App control de permisos\.venv\Lib\site-packages\werkzeug\wrappers\request.py", line 604, in get_json
    return self.on_json_loading_failed(None)
           ^^^^^^^^^^^^^^^^^^^^^^^^^^^^^^^^^
  File "D:\Terranova\proyectos\App control de permisos\.venv\Lib\site-packages\flask\wrappers.py", line 131, in on_json_loading_failed
    return super().on_json_loading_failed(e)
           ^^^^^^^^^^^^^^^^^^^^^^^^^^^^^^^^^
  File "D:\Terranova\proyectos\App control de permisos\.venv\Lib\site-packages\werkzeug\wrappers\request.py", line 647, in on_json_loading_failed
    raise UnsupportedMediaType(
werkzeug.exceptions.UnsupportedMediaType: 415 Unsupported Media Type: Did not attempt to load JSON data because the request Content-Type was not 'application/json'.

2024-03-12 22:12:10 | ERROR | test error
2024-03-12 22:12:10 | ERROR | Traceback (most recent call last):
  File "D:\Terranova\proyectos\App control de permisos\src\routes\PermissionRoutes.py", line 62, in create_permission
    raise ValueError('test error')
ValueError: test error

2024-03-12 22:12:46 | ERROR | test error
2024-03-12 22:12:46 | ERROR | Traceback (most recent call last):
  File "D:\Terranova\proyectos\App control de permisos\src\routes\PermissionRoutes.py", line 62, in create_permission
    raise ValueError('test error')
ValueError: test error

2024-03-12 23:01:30 | ERROR | 'NoneType' object has no attribute 'dni'
2024-03-12 23:01:30 | ERROR | Traceback (most recent call last):
  File "D:\Terranova\proyectos\App control de permisos\src\services\PermissionService.py", line 86, in create_permission
    (permission.dni, permission.permission_date, permission.start_time, permission.end_time, permission.reason, permission.status, permission.observation, permission.validator_id))
     ^^^^^^^^^^^^^^
AttributeError: 'NoneType' object has no attribute 'dni'

2024-03-12 23:03:11 | ERROR | 'NoneType' object has no attribute 'dni'
2024-03-12 23:03:11 | ERROR | Traceback (most recent call last):
  File "D:\Terranova\proyectos\App control de permisos\src\services\PermissionService.py", line 86, in create_permission
    (permission.dni, permission.permission_date, permission.start_time, permission.end_time, permission.reason, permission.status, permission.observation, permission.validator_id))
     ^^^^^^^^^^^^^^
AttributeError: 'NoneType' object has no attribute 'dni'

2024-03-12 23:04:54 | ERROR | 'NoneType' object has no attribute 'dni'
2024-03-12 23:04:54 | ERROR | Traceback (most recent call last):
  File "D:\Terranova\proyectos\App control de permisos\src\services\PermissionService.py", line 87, in create_permission
    (permission.dni, permission.permission_date, permission.start_time, permission.end_time, permission.reason, permission.status, permission.observation, permission.validator_id))
     ^^^^^^^^^^^^^^
AttributeError: 'NoneType' object has no attribute 'dni'

2024-03-12 23:06:05 | ERROR | la sintaxis de entrada no es válida para tipo timestamp: «09:00»
LINE 2: ...                VALUES ('47518569', '2024-03-12', '09:00', '...
                                                             ^

2024-03-12 23:06:05 | ERROR | Traceback (most recent call last):
  File "D:\Terranova\proyectos\App control de permisos\src\services\PermissionService.py", line 84, in create_permission
    cursor.execute("""INSERT INTO permissions (dni, permission_date, start_time, end_time, reason, status, observation, validator_id)
psycopg2.errors.InvalidDatetimeFormat: la sintaxis de entrada no es válida para tipo timestamp: «09:00»
LINE 2: ...                VALUES ('47518569', '2024-03-12', '09:00', '...
                                                             ^


2024-03-12 23:14:09 | ERROR | la columna «start_time» es de tipo timestamp without time zone pero la expresión es de tipo time without time zone
LINE 2: ...                VALUES ('47518569', '2024-03-12', '09:00:00'...
                                                             ^
HINT:  Necesitará reescribir la expresión o aplicarle una conversión de tipo.

2024-03-12 23:14:09 | ERROR | Traceback (most recent call last):
  File "D:\Terranova\proyectos\App control de permisos\src\services\PermissionService.py", line 87, in create_permission
    cursor.execute("""INSERT INTO permissions (dni, permission_date, start_time, end_time, reason, status, observation, validator_id)
psycopg2.errors.DatatypeMismatch: la columna «start_time» es de tipo timestamp without time zone pero la expresión es de tipo time without time zone
LINE 2: ...                VALUES ('47518569', '2024-03-12', '09:00:00'...
                                                             ^
HINT:  Necesitará reescribir la expresión o aplicarle una conversión de tipo.


2024-03-12 23:15:01 | ERROR | type object 'Permission' has no attribute 'dni'
2024-03-12 23:15:01 | ERROR | Traceback (most recent call last):
  File "D:\Terranova\proyectos\App control de permisos\src\routes\PermissionRoutes.py", line 63, in create_permission
    return jsonify({'message': 'success', 'data': {'dni': Permission.dni}})
                                                          ^^^^^^^^^^^^^^
AttributeError: type object 'Permission' has no attribute 'dni'

2024-03-12 23:16:36 | ERROR | type object 'Permission' has no attribute 'dni'
2024-03-12 23:16:36 | ERROR | Traceback (most recent call last):
  File "D:\Terranova\proyectos\App control de permisos\src\routes\PermissionRoutes.py", line 63, in create_permission
    return jsonify({'message': 'success', 'data': {'dni': Permission.dni}})
                                                          ^^^^^^^^^^^^^^
AttributeError: type object 'Permission' has no attribute 'dni'

2024-03-12 23:51:57 | ERROR | no existe la columna «create_at»
LINE 2: ..._time, reason, status, observation, validator_id, create_at,...
                                                             ^
HINT:  Probablemente quiera hacer referencia a la columna «p.created_at».

2024-03-12 23:51:57 | ERROR | object of type 'NoneType' has no len()
2024-03-12 23:51:57 | ERROR | Traceback (most recent call last):
  File "D:\Terranova\proyectos\App control de permisos\src\routes\PermissionRoutes.py", line 18, in index
    if (len(permissions) > 0):
        ^^^^^^^^^^^^^^^^
TypeError: object of type 'NoneType' has no len()

2024-03-12 23:52:28 | ERROR | no existe la columna «create_at»
LINE 2: ..._time, reason, status, observation, validator_id, create_at,...
                                                             ^
HINT:  Probablemente quiera hacer referencia a la columna «p.created_at».

2024-03-12 23:52:28 | ERROR | object of type 'NoneType' has no len()
2024-03-12 23:52:28 | ERROR | Traceback (most recent call last):
  File "D:\Terranova\proyectos\App control de permisos\src\routes\PermissionRoutes.py", line 18, in index
    if (len(permissions) > 0):
        ^^^^^^^^^^^^^^^^
TypeError: object of type 'NoneType' has no len()

2024-03-12 23:53:13 | ERROR | no existe la columna «create_at»
LINE 2: ..._time, reason, status, observation, validator_id, create_at,...
                                                             ^
HINT:  Probablemente quiera hacer referencia a la columna «p.created_at».

2024-03-12 23:53:13 | ERROR | object of type 'NoneType' has no len()
2024-03-12 23:53:13 | ERROR | Traceback (most recent call last):
  File "D:\Terranova\proyectos\App control de permisos\src\routes\PermissionRoutes.py", line 19, in index
    if (len(permissions) > 0):
        ^^^^^^^^^^^^^^^^
TypeError: object of type 'NoneType' has no len()

2024-03-12 23:55:49 | ERROR | no existe la columna «create_at»
LINE 2: ..._time, reason, status, observation, validator_id, create_at,...
                                                             ^
HINT:  Probablemente quiera hacer referencia a la columna «p.created_at».

2024-03-12 23:55:49 | ERROR | object of type 'NoneType' has no len()
2024-03-12 23:55:49 | ERROR | Traceback (most recent call last):
  File "D:\Terranova\proyectos\App control de permisos\src\routes\PermissionRoutes.py", line 19, in index
    if (len(permissions) > 0):
        ^^^^^^^^^^^^^^^^
TypeError: object of type 'NoneType' has no len()

2024-03-12 23:56:50 | ERROR | no existe la columna «create_at»
LINE 2: ..._time, reason, status, observation, validator_id, create_at,...
                                                             ^
HINT:  Probablemente quiera hacer referencia a la columna «p.created_at».

2024-03-12 23:56:50 | ERROR | object of type 'NoneType' has no len()
2024-03-12 23:56:50 | ERROR | Traceback (most recent call last):
  File "D:\Terranova\proyectos\App control de permisos\src\routes\PermissionRoutes.py", line 19, in index
    if (len(permissions) > 0):
        ^^^^^^^^^^^^^^^^
TypeError: object of type 'NoneType' has no len()

